Traceback (most recent call last):
  File "/Users/cfanelli/Desktop/teaching/BRDS/brds_env/lib/python3.9/site-packages/jupyter_cache/executors/utils.py", line 51, in single_nb_execution
    executenb(
  File "/Users/cfanelli/Desktop/teaching/BRDS/brds_env/lib/python3.9/site-packages/nbclient/client.py", line 1204, in execute
    return NotebookClient(nb=nb, resources=resources, km=km, **kwargs).execute()
  File "/Users/cfanelli/Desktop/teaching/BRDS/brds_env/lib/python3.9/site-packages/nbclient/util.py", line 84, in wrapped
    return just_run(coro(*args, **kwargs))
  File "/Users/cfanelli/Desktop/teaching/BRDS/brds_env/lib/python3.9/site-packages/nbclient/util.py", line 62, in just_run
    return loop.run_until_complete(coro)
  File "/usr/local/Cellar/python@3.9/3.9.2_1/Frameworks/Python.framework/Versions/3.9/lib/python3.9/asyncio/base_events.py", line 642, in run_until_complete
    return future.result()
  File "/Users/cfanelli/Desktop/teaching/BRDS/brds_env/lib/python3.9/site-packages/nbclient/client.py", line 663, in async_execute
    await self.async_execute_cell(
  File "/Users/cfanelli/Desktop/teaching/BRDS/brds_env/lib/python3.9/site-packages/nbclient/client.py", line 965, in async_execute_cell
    await self._check_raise_for_error(cell, cell_index, exec_reply)
  File "/Users/cfanelli/Desktop/teaching/BRDS/brds_env/lib/python3.9/site-packages/nbclient/client.py", line 862, in _check_raise_for_error
    raise CellExecutionError.from_cell_and_msg(cell, exec_reply_content)
nbclient.exceptions.CellExecutionError: An error occurred while executing the following cell:
------------------
data_ppc = az.from_pymc3(trace=trace_g, posterior_predictive=y_pred_g)
ax = az.plot_ppc(data_ppc, figsize=(12, 6), mean=False)
ax[0].legend(fontsize=15)
plt.savefig('./output/B11197_02_11.png', dpi=300)
------------------

[0;31m---------------------------------------------------------------------------[0m
[0;31mTypeError[0m                                 Traceback (most recent call last)
Input [0;32mIn [20][0m, in [0;36m<cell line: 3>[0;34m()[0m
[1;32m      1[0m data_ppc [38;5;241m=[39m az[38;5;241m.[39mfrom_pymc3(trace[38;5;241m=[39mtrace_g, posterior_predictive[38;5;241m=[39my_pred_g)
[1;32m      2[0m ax [38;5;241m=[39m az[38;5;241m.[39mplot_ppc(data_ppc, figsize[38;5;241m=[39m([38;5;241m12[39m, [38;5;241m6[39m), mean[38;5;241m=[39m[38;5;28;01mFalse[39;00m)
[0;32m----> 3[0m [43max[49m[43m[[49m[38;5;241;43m0[39;49m[43m][49m[38;5;241m.[39mlegend(fontsize[38;5;241m=[39m[38;5;241m15[39m)
[1;32m      4[0m plt[38;5;241m.[39msavefig([38;5;124m'[39m[38;5;124m./output/B11197_02_11.png[39m[38;5;124m'[39m, dpi[38;5;241m=[39m[38;5;241m300[39m)

[0;31mTypeError[0m: 'AxesSubplot' object is not subscriptable
TypeError: 'AxesSubplot' object is not subscriptable

